<?xml version="1.0"?>
<robot xmlns:xacro="http://www.ros.org/wiki/xacro" >

    <xacro:include filename="inertial_macros.xacro"/>

    <material name="white">
        <color rgba="1 1 1 1" />
    </material>

    <material name="orange">
        <color rgba="1 0.3 0.1 1"/>
    </material>

    <material name="blue">
        <color rgba="0.2 0.2 1 1"/>
    </material>

    <material name="black">
        <color rgba="0 0 0 1"/>
    </material>

    <material name="red">
        <color rgba="1 0 0 1"/>
    </material>

    <!-- BASE LINK -->

    <link name="base_link">

    </link>

    <!-- BASE_FOOTPRINT LINK -->

    <joint name="base_footprint_joint" type="fixed">
        <parent link="base_link"/>
        <child link="base_footprint"/>
        <origin xyz="0 0 0" rpy="0 0 0"/>
    </joint>

    <link name="base_footprint">
    </link>

    <!-- CHASSIS LINK -->

    <joint name="chassis_joint" type="fixed">
        <parent link="base_link"/>
        <child link="chassis"/>
        <origin xyz="-0.1 0 0"/>
    </joint>

    <link name="chassis">
        <visual>
            <origin xyz="0.15 0 0.075"/>
            <geometry>
                <box size="0.3 0.3 0.15"/>
            </geometry>
            <material name="white"/>
        </visual>
        <collision>
            <origin xyz="0.15 0 0.075"/>
            <geometry>
                <box size="0.3 0.3 0.15"/>
            </geometry>
        </collision>
        <xacro:inertial_box mass="0.5" x="0.3" y="0.3" z="0.15">
            <origin xyz="0.15 0 0.075" rpy="0 0 0"/>
        </xacro:inertial_box>
    </link>
    
    <gazebo reference="chassis">
        <material>Gazebo/White</material>
    </gazebo>


    <!-- LEFT  front WHEEL LINK -->

    <joint name="left_front_wheel_joint" type="continuous">
        <parent link="base_link"/>
        <child link="left_front_wheel"/>
        <origin xyz="0.15 0.175 0" rpy="-${pi/2} 0 0" />
        <axis xyz="0 0 1"/>
    </joint>

    <link name="left_front_wheel">
        <visual>
            <geometry>
                <cylinder radius="0.05" length="0.04"/>
            </geometry>
            <material name="blue"/>
        </visual>
        <collision>
            <geometry>
                <cylinder radius="0.05" length="0.04"/>
            </geometry>
        </collision>
        <xacro:inertial_cylinder mass="0.1" length="0.04" radius="0.05">
            <origin xyz="0 0 0" rpy="0 0 0"/>
        </xacro:inertial_cylinder>
    </link>

    <gazebo reference="left_front_wheel">
        <material>Gazebo/Blue</material>
    </gazebo>

    <!-- RIGHT WHEEL LINK -->

    <joint name="right_front_wheel_joint" type="continuous">
        <parent link="base_link"/>
        <child link="right_front_wheel"/>
        <origin xyz="0.15 -0.175 0" rpy="${pi/2} 0 0" />
        <axis xyz="0 0 -1"/>
    </joint>

    <link name="right_front_wheel">
        <visual>
            <geometry>
                <cylinder radius="0.05" length="0.04"/>
            </geometry>
            <material name="blue"/>
        </visual>
        <collision>
            <geometry>
                <cylinder radius="0.05" length="0.04"/>
            </geometry>
        </collision>
        <xacro:inertial_cylinder mass="0.1" length="0.04" radius="0.05">
            <origin xyz="0 0 0" rpy="0 0 0"/>
        </xacro:inertial_cylinder>
    </link>

    <gazebo reference="right_front_wheel">
        <material>Gazebo/Blue</material>
    </gazebo>

    <!-- CASTER WHEEL LINK -->

    <!-- <joint name="caster_wheel_joint" type="fixed">
        <parent link="chassis"/>
        <child link="caster_wheel"/>
        <origin xyz="0.06 0 0"/>
    </joint>


    <link name="caster_wheel">
        <visual>
            <geometry>
                <sphere radius="0.05"/>
            </geometry>
            <material name="black"/>
        </visual>
        <collision>
            <geometry>
                <sphere radius="0.05"/>
            </geometry>
        </collision>
        <xacro:inertial_sphere mass="0.1" radius="0.05">
            <origin xyz="0 0 0" rpy="0 0 0"/>
        </xacro:inertial_sphere>
    </link> -->

    <!-- <gazebo reference="caster_wheel">
        <material>Gazebo/Black</material>
    </gazebo> -->

    
    

    <!-- left back wheel LINK  -->
    <joint name="left_back_wheel_joint" type="continuous">
        <parent link="base_link"/>
        <child link="left_back_wheel"/>
        <origin xyz="0.0 0.175 0" rpy="-${pi/2} 0 0" />
        <axis xyz="0 0 1"/>
    </joint>

    <link name="left_back_wheel">
        <visual>
            <geometry>
                <cylinder radius="0.05" length="0.04"/>
            </geometry>
            <material name="blue"/>
        </visual>
        <collision>
            <geometry>
                <cylinder radius="0.05" length="0.04"/>
            </geometry>
        </collision>
        <xacro:inertial_cylinder mass="0.1" length="0.04" radius="0.05">
            <origin xyz="0 0 0" rpy="0 0 0"/>
        </xacro:inertial_cylinder>
    </link>
    <gazebo reference="left_back_wheel">
        <material>Gazebo/Blue</material>
        <mu1>0.001</mu1>
        <mu2>0.001</mu2>
    </gazebo>

    <!-- RIGHT back WHEEL LINK -->

    <joint name="right_back_wheel_joint" type="continuous">
        <parent link="base_link"/>
        <child link="right_back_wheel"/>
        <origin xyz="0.0 -0.175 0" rpy="${pi/2} 0 0" />
        <axis xyz="0 0 -1"/>
    </joint>

    <link name="right_back_wheel">
        <visual>
            <geometry>
                <cylinder radius="0.05" length="0.04"/>
            </geometry>
            <material name="blue"/>
        </visual>
        <collision>
            <geometry>
                <cylinder radius="0.05" length="0.04"/>
            </geometry>
        </collision>
        <xacro:inertial_cylinder mass="0.1" length="0.04" radius="0.05">
            <origin xyz="0 0 0" rpy="0 0 0"/>
        </xacro:inertial_cylinder>


    </link>

    <gazebo reference="right_back_wheel">
        <material>Gazebo/Blue</material>
        <mu1>0.001</mu1>
        <mu2>0.001</mu2>
    </gazebo>






</robot>